<?xml version="1.0" encoding="UTF-8"?>
<testng-results skipped="0" failed="1" total="4" passed="3">
  <reporter-output>
  </reporter-output>
  <suite name="Default suite" duration-ms="47" started-at="2019-05-29T01:20:33Z" finished-at="2019-05-29T01:20:33Z">
    <groups>
    </groups>
    <test name="Default test" duration-ms="47" started-at="2019-05-29T01:20:33Z" finished-at="2019-05-29T01:20:33Z">
      <class name="exemple.Demotest">
        <test-method status="PASS" signature="divi()[pri:0, instance:exemple.Demotest@2f7a2457]" name="divi" duration-ms="16" started-at="2019-05-29T03:20:33Z" finished-at="2019-05-29T03:20:33Z">
          <reporter-output>
          </reporter-output>
        </test-method> <!-- divi -->
        <test-method status="PASS" signature="sum()[pri:0, instance:exemple.Demotest@2f7a2457]" name="sum" duration-ms="0" started-at="2019-05-29T03:20:33Z" finished-at="2019-05-29T03:20:33Z">
          <reporter-output>
          </reporter-output>
        </test-method> <!-- sum -->
        <test-method status="FAIL" signature="muli()[pri:0, instance:exemple.Demotest@2f7a2457]" name="muli" duration-ms="0" started-at="2019-05-29T03:20:33Z" finished-at="2019-05-29T03:20:33Z">
          <exception class="java.lang.AssertionError">
            <message>
              <![CDATA[expected:<7> but was:<8>]]>
            </message>
            <full-stacktrace>
              <![CDATA[java.lang.AssertionError: expected:<7> but was:<8>
	at org.testng.AssertJUnit.fail(AssertJUnit.java:59)
	at org.testng.AssertJUnit.failNotEquals(AssertJUnit.java:364)
	at org.testng.AssertJUnit.assertEquals(AssertJUnit.java:80)
	at org.testng.AssertJUnit.assertEquals(AssertJUnit.java:245)
	at org.testng.AssertJUnit.assertEquals(AssertJUnit.java:252)
	at exemple.Demotest.muli(Demotest.java:24)
	at sun.reflect.NativeMethodAccessorImpl.invoke0(Native Method)
	at sun.reflect.NativeMethodAccessorImpl.invoke(Unknown Source)
	at sun.reflect.DelegatingMethodAccessorImpl.invoke(Unknown Source)
	at java.lang.reflect.Method.invoke(Unknown Source)
	at org.testng.internal.MethodInvocationHelper.invokeMethod(MethodInvocationHelper.java:86)
	at org.testng.internal.Invoker.invokeMethod(Invoker.java:645)
	at org.testng.internal.Invoker.invokeTestMethod(Invoker.java:822)
	at org.testng.internal.Invoker.invokeTestMethods(Invoker.java:1130)
	at org.testng.internal.TestMethodWorker.invokeTestMethods(TestMethodWorker.java:129)
	at org.testng.internal.TestMethodWorker.run(TestMethodWorker.java:112)
	at org.testng.TestRunner.privateRun(TestRunner.java:782)
	at org.testng.TestRunner.run(TestRunner.java:632)
	at org.testng.SuiteRunner.runTest(SuiteRunner.java:366)
	at org.testng.SuiteRunner.runSequentially(SuiteRunner.java:361)
	at org.testng.SuiteRunner.privateRun(SuiteRunner.java:319)
	at org.testng.SuiteRunner.run(SuiteRunner.java:268)
	at org.testng.SuiteRunnerWorker.runSuite(SuiteRunnerWorker.java:52)
	at org.testng.SuiteRunnerWorker.run(SuiteRunnerWorker.java:86)
	at org.testng.TestNG.runSuitesSequentially(TestNG.java:1244)
	at org.testng.TestNG.runSuitesLocally(TestNG.java:1169)
	at org.testng.TestNG.run(TestNG.java:1064)
	at org.testng.remote.RemoteTestNG.run(RemoteTestNG.java:113)
	at org.testng.remote.RemoteTestNG.initAndRun(RemoteTestNG.java:206)
	at org.testng.remote.RemoteTestNG.main(RemoteTestNG.java:177)
]]>
            </full-stacktrace>
          </exception> <!-- java.lang.AssertionError -->
          <reporter-output>
          </reporter-output>
        </test-method> <!-- muli -->
        <test-method status="PASS" signature="sous()[pri:0, instance:exemple.Demotest@2f7a2457]" name="sous" duration-ms="0" started-at="2019-05-29T03:20:33Z" finished-at="2019-05-29T03:20:33Z">
          <reporter-output>
          </reporter-output>
        </test-method> <!-- sous -->
      </class> <!-- exemple.Demotest -->
    </test> <!-- Default test -->
  </suite> <!-- Default suite -->
</testng-results>
